Workbook

Sheet HOME
C3: LUSAKA OAKTREE SCHOOL
G6: LUSAKA OAKTREE SCHOOL
H8: School management system
C16: ALEVEL | E16: ASLEVEL | G16: IGCSE 1 | I16: LS3A | J16: LS3B | L16: LS2A | M16: LS2B | N16: LS1B | P16: LS1A F
C18: A LEVEL REPORT CARD | G18: LS3 A REPORT CARD | J18: LS1 A REPORT CARD F
C20: AS LEVEL REPORT CARD | G20: LS3 B REPORT CARD | J20: LS1 B REPORT CARD
D22: IGCSE 2 REPORT CARD | G22: LS2 A REPORT CARD
C24: IGCSE 1 REPORT CARD | G24: LS2 B REPORT CARD

Sheet Overall Analysis
D2: SECONDARY RESULTS ANALYSIS
B5: LS1 A
B6: ENGLISH | C6: MATHEMATICS | D6: SCIENCE | E6: SOCIAL STUDIES | F6: NEW COMPUTING | G6: BUSINESS STUDIES | H6: FRENCH | I6: ART | J6: MDD | K6: PE
A7: Average | B7: =LS1A!E36 -> 63.375 | C7: =LS1A!I36 -> 46.458333 | D7: =LS1A!M36 -> 53.208333 | E7: =LS1A!Q36 -> 67.666667 | F7: =LS1A!U36 -> 65.291667 | G7: =LS1A!Y36 -> 63.375 | H7: =LS1A!AC36 -> 61.333333 | I7: =LS1A!AG36 -> 73.625 | J7: =LS1A!AK36 -> 76.333333 | K7: =LS1A!AO36 -> 66.941667
A8: NO. Students | B8: =LS1A!E37 -> 24 | C8: =LS1A!I37 -> 24 | D8: =LS1A!M37 -> 24 | E8: =LS1A!Q37 -> 24 | F8: =LS1A!U37 -> 24 | G8: =LS1A!Y37 -> 24 | H8: =LS1A!AC37 -> 24 | I8: =LS1A!AG37 -> 24 | J8: =LS1A!AK37 -> 24 | K8: =LS1A!AO37 -> 24
A9: Pass | B9: =LS1A!E38 -> 21 | C9: =LS1A!I38 -> 12 | D9: =LS1A!M38 -> 11 | E9: =LS1A!Q38 -> 21 | F9: =LS1A!U38 -> 22 | G9: =LS1A!Y38 -> 21 | H9: =LS1A!AC38 -> 15 | I9: =LS1A!AG38 -> 24 | J9: =LS1A!AK38 -> 24 | K9: =LS1A!AO38 -> 22
A10: Fail | B10: =LS1A!E39 -> 3 | C10: =LS1A!I39 -> 12 | D10: =LS1A!M39 -> 13 | E10: =LS1A!Q39 -> 3 | F10: =LS1A!U39 -> 2 | G10: =LS1A!Y39 -> 3 | H10: =LS1A!AC39 -> 9 | I10: =LS1A!AG39 -> 0 | J10: =LS1A!AK39 -> 0 | K10: =LS1A!AO39 -> 2
A11: Pass Rate % | B11: =LS1A!E40 -> 87.5 | C11: =LS1A!I40 -> 50 | D11: =LS1A!M40 -> 45.833333 | E11: =LS1A!Q40 -> 87.5 | F11: =LS1A!U40 -> 91.666667 | G11: =LS1A!Y40 -> 87.5 | H11: =LS1A!AC40 -> 62.5 | I11: =LS1A!AG40 -> 100 | J11: =LS1A!AK40 -> 100 | K11: =LS1A!AO40 -> 91.666667
B14: LS1 B
B15: ENGLISH | C15: MATHEMATICS | D15: SCIENCE | E15: SOCIAL STUDIES | F15: NEW COMPUTING | G15: BUSINESS STUDIES | H15: FRENCH | I15: ART | J15: MDD | K15: PE
A16: Average | B16: =LS1B!E35 -> 65.962963 | C16: =LS1B!I35 -> 52.555556 | D16: =LS1B!M35 -> 58.937037 | E16: =LS1B!Q35 -> 61.666667 | F16: =LS1B!U35 -> 68.777778 | G16: =LS1B!Y35 -> 70.888889 | H16: =LS1B!AC35 -> 70.076923 | I16: =LS1B!AG35 -> 75.740741 | J16: =LS1B!AK35 -> 68.814815 | K16: =LS1B!AO35 -> 66.862963
A17: NO. Students | B17: =LS1B!E36 -> 27 | C17: =LS1B!I36 -> 27 | D17: =LS1B!M36 -> 27 | E17: =LS1B!Q36 -> 27 | F17: =LS1B!U36 -> 27 | G17: =LS1B!Y36 -> 27 | H17: =LS1B!AC36 -> 26 | I17: =LS1B!AG36 -> 27 | J17: =LS1B!AK36 -> 27 | K17: =LS1B!AO36 -> 27
A18: Pass | B18: =LS1B!E37 -> 26 | C18: =LS1B!I37 -> 17 | D18: =LS1B!M37 -> 19 | E18: =LS1B!Q37 -> 23 | F18: =LS1B!U37 -> 26 | G18: =LS1B!Y37 -> 26 | H18: =LS1B!AC37 -> 21 | I18: =LS1B!AG37 -> 27 | J18: =LS1B!AK37 -> 24 | K18: =LS1B!AO37 -> 27
A19: Fail | B19: =LS1B!E38 -> 1 | C19: =LS1B!I38 -> 10 | D19: =LS1B!M38 -> 8 | E19: =LS1B!Q38 -> 4 | F19: =LS1B!U38 -> 1 | G19: =LS1B!Y38 -> 1 | H19: =LS1B!AC38 -> 5 | I19: =LS1B!AG38 -> 0 | J19: =LS1B!AK38 -> 3 | K19: =LS1B!AO38 -> 0
A20: Pass Rate % | B20: =LS1B!E39 -> 96.296296 | C20: =LS1B!I39 -> 62.962963 | D20: =LS1B!M39 -> 70.37037 | E20: =LS1B!Q39 -> 85.185185 | F20: =LS1B!U39 -> 96.296296 | G20: =LS1B!Y39 -> 96.296296 | H20: =LS1B!AC39 -> 80.769231 | I20: =LS1B!AG39 -> 100 | J20: =LS1B!AK39 -> 88.888889 | K20: =LS1B!AO39 -> 100
B23: LS2 A
B24: ENGLISH | C24: MATHEMATICS | D24: SCIENCE | E24: SOCIAL STUDIES | F24: NEW COMPUTING | G24: BUSINESS STUDIES | H24: FRENCH | I24: ART | J24: MDD | K24: PE
A25: Average | B25: =LS2A!E34 -> 50.48 | C25: =LS2A!I34 -> 53.52 | D25: =LS2A!M34 -> 61.48 | E25: =LS2A!Q34 -> 63.48 | F25: =LS2A!U34 -> 69.56 | G25: =LS2A!Y34 -> 71.24 | H25: =LS2A!AC34 -> 61.8 | I25: =LS2A!AG34 -> 68.48 | J25: =LS2A!AK34 -> 71.68 | K25: =LS2A!AO34 -> 67.744
A26: NO. Students | B26: =LS2A!E35 -> 25 | C26: =LS2A!I35 -> 25 | D26: =LS2A!M35 -> 25 | E26: =LS2A!Q35 -> 25 | F26: =LS2A!U35 -> 25 | G26: =LS2A!Y35 -> 25 | H26: =LS2A!AC35 -> 25 | I26: =LS2A!AG35 -> 25 | J26: =LS2A!AK35 -> 25 | K26: =LS2A!AO35 -> 25
A27: Pass | B27: =LS2A!E36 -> 17 | C27: =LS2A!I36 -> 15 | D27: =LS2A!M36 -> 21 | E27: =LS2A!Q36 -> 21 | F27: =LS2A!U36 -> 22 | G27: =LS2A!Y36 -> 22 | H27: =LS2A!AC36 -> 21 | I27: =LS2A!AG36 -> 23 | J27: =LS2A!AK36 -> 23 | K27: =LS2A!AO36 -> 24
A28: Fail | B28: =LS2A!E37 -> 8 | C28: =LS2A!I37 -> 10 | D28: =LS2A!M37 -> 4 | E28: =LS2A!Q37 -> 4 | F28: =LS2A!U37 -> 3 | G28: =LS2A!Y37 -> 3 | H28: =LS2A!AC37 -> 4 | I28: =LS2A!AG37 -> 2 | J28: =LS2A!AK37 -> 2 | K28: =LS2A!AO37 -> 1
A29: Pass Rate % | B29: =LS2A!E38 -> 68 | C29: =LS2A!I38 -> 60 | D29: =LS2A!M38 -> 84 | E29: =LS2A!Q38 -> 84 | F29: =LS2A!U38 -> 88 | G29: =LS2A!Y38 -> 88 | H29: =LS2A!AC38 -> 84 | I29: =LS2A!AG38 -> 92 | J29: =LS2A!AK38 -> 92 | K29: =LS2A!AO38 -> 96
B32: LS2 B
B33: ENGLISH | C33: MATHEMATICS | D33: SCIENCE | E33: SOCIAL STUDIES | F33: NEW COMPUTING | G33: BUSINESS STUDIES | H33: FRENCH | I33: ART | J33: MDD | K33: PE
A34: Average | B34: =LS2B!E30 -> 57.5 | C34: =LS2B!I30 -> 64.833333 | D34: =LS2B!M30 -> 69.555556 | E34: =LS2B!Q30 -> 71.944444 | F34: =LS2B!U30 -> 86 | G34: =LS2B!Y30 -> 78.722222 | H34: =LS2B!AC30 -> 73.055556 | I34: =LS2B!AG30 -> 74.666667 | J34: =LS2B!AK30 -> 71.666667 | K34: =LS2B!AO30 -> 71.527778
A35: NO. Students | B35: =LS2B!E31 -> 18 | C35: =LS2B!I31 -> 18 | D35: =LS2B!M31 -> 18 | E35: =LS2B!Q31 -> 18 | F35: =LS2B!U31 -> 18 | G35: =LS2B!Y31 -> 18 | H35: =LS2B!AC31 -> 18 | I35: =LS2B!AG31 -> 18 | J35: =LS2B!AK31 -> 18 | K35: =LS2B!AO31 -> 18
A36: Pass | B36: =LS2B!E32 -> 16 | C36: =LS2B!I32 -> 16 | D36: =LS2B!M32 -> 16 | E36: =LS2B!Q32 -> 17 | F36: =LS2B!U32 -> 17 | G36: =LS2B!Y32 -> 17 | H36: =LS2B!AC32 -> 17 | I36: =LS2B!AG32 -> 18 | J36: =LS2B!AK32 -> 18 | K36: =LS2B!AO32 -> 18
A37: Fail | B37: =LS2B!E33 -> 2 | C37: =LS2B!I33 -> 2 | D37: =LS2B!M33 -> 2 | E37: =LS2B!Q33 -> 1 | F37: =LS2B!U33 -> 1 | G37: =LS2B!Y33 -> 1 | H37: =LS2B!AC33 -> 1 | I37: =LS2B!AG33 -> 0 | J37: =LS2B!AK33 -> 0 | K37: =LS2B!AO33 -> 0
A38: Pass Rate % | B38: =LS2B!E34 -> 88.888889 | C38: =LS2B!I34 -> 88.888889 | D38: =LS2B!M34 -> 88.888889 | E38: =LS2B!Q34 -> 94.444444 | F38: =LS2B!U34 -> 94.444444 | G38: =LS2B!Y34 -> 94.444444 | H38: =LS2B!AC34 -> 94.444444 | I38: =LS2B!AG34 -> 100 | J38: =LS2B!AK34 -> 100 | K38: =LS2B!AO34 -> 100
B41: LS3 A
B42: ENGLISH | C42: MATHEMATICS | D42: SCIENCE | E42: SOCIAL STUDIES | F42: NEW COMPUTING | G42: BUSINESS STUDIES | H42: FRENCH | I42: ART | J42: MDD | K42: PE
A43: Average | B43: =LS3A!E31 -> 55.26087 | C43: =LS3A!I31 -> 54.391304 | D43: =LS3A!M31 -> 56.430435 | E43: =LS3A!Q31 -> 60.043478 | F43: =LS3A!U31 -> 62.913043 | G43: =LS3A!Y31 -> 66.869565 | H43: =LS3A!AC31 -> 64.478261 | I43: =LS3A!AG31 -> 73.869565 | J43: =LS3A!AK31 -> 78.565217 | K43: =LS3A!AO31 -> 61.478261
A44: NO. Students | B44: =LS3A!E32 -> 23 | C44: =LS3A!I32 -> 23 | D44: =LS3A!M32 -> 23 | E44: =LS3A!Q32 -> 23 | F44: =LS3A!U32 -> 23 | G44: =LS3A!Y32 -> 23 | H44: =LS3A!AC32 -> 23 | I44: =LS3A!AG32 -> 23 | J44: =LS3A!AK32 -> 23 | K44: =LS3A!AO32 -> 23
A45: Pass | B45: =LS3A!E33 -> 17 | C45: =LS3A!I33 -> 15 | D45: =LS3A!M33 -> 17 | E45: =LS3A!Q33 -> 20 | F45: =LS3A!U33 -> 21 | G45: =LS3A!Y33 -> 20 | H45: =LS3A!AC33 -> 19 | I45: =LS3A!AG33 -> 23 | J45: =LS3A!AK33 -> 23 | K45: =LS3A!AO33 -> 21
A46: Fail | B46: =LS3A!E34 -> 6 | C46: =LS3A!I34 -> 8 | D46: =LS3A!M34 -> 6 | E46: =LS3A!Q34 -> 3 | F46: =LS3A!U34 -> 2 | G46: =LS3A!Y34 -> 3 | H46: =LS3A!AC34 -> 4 | I46: =LS3A!AG34 -> 0 | J46: =LS3A!AK34 -> 0 | K46: =LS3A!AO34 -> 2
A47: Pass Rate % | B47: =LS3A!E35 -> 73.913043 | C47: =LS3A!I35 -> 65.217391 | D47: =LS3A!M35 -> 73.913043 | E47: =LS3A!Q35 -> 86.956522 | F47: =LS3A!U35 -> 91.304348 | G47: =LS3A!Y35 -> 86.956522 | H47: =LS3A!AC35 -> 82.608696 | I47: =LS3A!AG35 -> 100 | J47: =LS3A!AK35 -> 100 | K47: =LS3A!AO35 -> 91.304348
B50: LS3 B
B51: ENGLISH | C51: MATHEMATICS | D51: SCIENCE | E51: SOCIAL STUDIES | F51: NEW COMPUTING | G51: BUSINESS STUDIES | H51: FRENCH | I51: ART | J51: MDD | K51: PE
A52: Average | B52: =LS3B!E36 -> 54.48 | C52: =LS3B!I36 -> 54 | D52: =LS3B!M36 -> 57.34 | E52: =LS3B!Q36 -> 62.36 | F52: =LS3B!U36 -> 55.76 | G52: =LS3B!Y36 -> 66.56 | H52: =LS3B!AC36 -> 58.2 | I52: =LS3B!AG36 -> 75.6 | J52: =LS3B!AK36 -> 57.6 | K52: =LS3B!AO36 -> 68.624
A53: NO. Students | B53: =LS3B!E37 -> 25 | C53: =LS3B!I37 -> 25 | D53: =LS3B!M37 -> 25 | E53: =LS3B!Q37 -> 25 | F53: =LS3B!U37 -> 25 | G53: =LS3B!Y37 -> 25 | H53: =LS3B!AC37 -> 25 | I53: =LS3B!AG37 -> 25 | J53: =LS3B!AK37 -> 25 | K53: =LS3B!AO37 -> 25
...

Sheet LS1A
A3: Roll N0. | B3: Name | C3: English | G3: Mathematics | K3: Science | O3: Global Perspective | S3: New Computing | W3: Business Studies | AA3: French | AE3: Art | AI3: MDD | AM3: PE | AR3: AVERAGE | AS3: POSITION | AT3: CREATIVITY | AU3: RESPECT | AV3: EXCELLENCE | AW3: EMPATHY | AX3: DISCIPLINE | AY3: CLASS TEACHER'S COMMENT
C4: Formative | D4: Summative | E4: Final Mark | F4: Grade | G4: Formative | H4: Summative | I4: Final Mark | J4: Grade | K4: Formative | L4: Summative | M4: Final Mark | N4: Grade | O4: Formative | P4: Summative | Q4: Final Mark | R4: Grade | S4: Formative | T4: Summative | U4: Final Mark | V4: Grade | W4: Formative | X4: Summative | Y4: Final Mark | Z4: Grade | AA4: Formative | AB4: Summative | AC4: Final Mark | AD4: Grade | AE4: Formative | AF4: Summative | AG4: Final Mark | AH4: Grade | AI4: Formative | AJ4: Summative | AK4: Final Mark | AL4: Grade | AM4: Formative | AN4: Summative | AO4: Final Mark | AP4: Grade
A5: 1 | B5: Maine Ralesite | C5: 31 | D5: 41 | E5: =C5+D5 -> 72 | F5: =VLOOKUP(E5,$B$44:$C$52,2) -> B | G5: 28 | H5: 45 | I5: =G5+H5 -> 73 | J5: =VLOOKUP(I5,$B$44:$C$52,2) -> B | K5: 32 | L5: 45 | M5: =K5+L5 -> 77 | N5: =VLOOKUP(M5,$B$44:$C$52,2) -> B | O5: 35 | P5: 50 | Q5: =O5+P5 -> 85 | R5: =VLOOKUP(Q5,$B$44:$C$52,2) -> A | S5: 33 | T5: 47 | U5: =S5+T5 -> 80 | V5: =VLOOKUP(U5,$B$44:$C$52,2) -> A | W5: 28 | X5: 43 | Y5: =W5+X5 -> 71 | Z5: =VLOOKUP(Y5,$B$44:$C$52,2) -> B | AA5: 30 | AB5: 38 | AC5: =AA5+AB5 -> 68 | AD5: =VLOOKUP(AC5,$B$44:$C$52,2) -> C | AE5: 28 | AF5: 49 | AG5: 77 | AH5: =VLOOKUP(AG5,$B$44:$C$52,2) -> B | AI5: 37 | AJ5: 45 | AK5: =AI5+AJ5 -> 82 | AL5: =VLOOKUP(AK5,$B$44:$C$52,2) -> A | AM5: 23 | AN5: 41 | AO5: =AM5+AN5 -> 64 | AP5: =VLOOKUP(AO5,$B$44:$C$52,2) -> C | AR5: =AVERAGE(E5,I5,M5,Q5,U5,Y5,AC5,AG5,AK5,AO5) -> 74.9 | AS5: =RANK(AR5,$AR$5:$AR$33) -> 5 | AT5: A | AU5: A+ | AV5: B | AW5: A | AX5: A+ | AY5: Ralesite is a very respectful and well-mannered student who works well in class. His academic performance is good, showing clear understanding of key concepts. To improve further, he should participate more actively and ask questions to deepen his understanding. Regular practice and reviewing class notes will strengthen his learning. I encourage Ralesite to continue his positive behaviour and maintain steady effort towards higher achievement.
A6: 2 | B6: AIsha | C6: 21 | D6: 35 | E6: =C6+D6 -> 56 | F6: =VLOOKUP(E6,$B$44:$C$52,2) -> D | G6: 9 | H6: 17 | I6: =G6+H6 -> 26 | J6: =VLOOKUP(I6,$B$44:$C$52,2) -> G | K6: 18 | L6: 30 | M6: =K6+L6 -> 48 | N6: =VLOOKUP(M6,$B$44:$C$52,2) -> E | O6: 23 | P6: 22 | Q6: =O6+P6 -> 45 | R6: =VLOOKUP(Q6,$B$44:$C$52,2) -> E | S6: 23 | T6: 37 | U6: =S6+T6 -> 60 | V6: =VLOOKUP(U6,$B$44:$C$52,2) -> C | W6: 16 | X6: 31 | Y6: =W6+X6 -> 47 | Z6: =VLOOKUP(Y6,$B$44:$C$52,2) -> E | AA6: 19 | AB6: 40 | AC6: =AA6+AB6 -> 59 | AD6: =VLOOKUP(AC6,$B$44:$C$52,2) -> D | AE6: 24 | AF6: 43 | AG6: =AE6+AF6 -> 67 | AH6: =VLOOKUP(AG6,$B$44:$C$52,2) -> C | AI6: 37 | AJ6: 45 | AK6: =AI6+AJ6 -> 82 | AL6: =VLOOKUP(AK6,$B$44:$C$52,2) -> A | AM6: 18.9 | AN6: 40 | AO6: =AM6+AN6 -> 58.9 | AP6: =VLOOKUP(AO6,$B$44:$C$52,2) -> D | AR6: =AVERAGE(E6,I6,M6,Q6,U6,Y6,AC6,AG6,AK6,AO6) -> 54.89 | AS6: =RANK(AR6,$AR$5:$AR$33) -> 20 | AT6: C | AU6: A | AV6: C | AW6: B | AX6: A | AY6: Aisha behaves well and participates positively in class. However, she needs to improve in Science, Maths, and English. Paying close attention during lessons and completing extra practice will help her strengthen her skills. Asking questions when unsure and revising daily will support her learning. I encourage her to remain focused and dedicated. With consistent effort, Aisha can make great progress.
A7: 3 | B7: Chokr Mohammad | C7: 19 | D7: 18 | E7: =C7+D7 -> 37 | F7: =VLOOKUP(E7,$B$44:$C$52,2) -> F | G7: 9 | H7: 14 | I7: =G7+H7 -> 23 | J7: =VLOOKUP(I7,$B$44:$C$52,2) -> G | K7: 15 | L7: 17 | M7: =K7+L7 -> 32 | N7: =VLOOKUP(M7,$B$44:$C$52,2) -> F | O7: 23 | P7: 21 | Q7: =O7+P7 -> 44 | R7: =VLOOKUP(Q7,$B$44:$C$52,2) -> E | S7: 10 | T7: 33 | U7: =S7+T7 -> 43 | V7: =VLOOKUP(U7,$B$44:$C$52,2) -> E | W7: 9 | X7: 10 | Y7: =W7+X7 -> 19 | Z7: =VLOOKUP(Y7,$B$44:$C$52,2) -> U | AA7: 16 | AB7: 23 | AC7: =AA7+AB7 -> 39 | AD7: =VLOOKUP(AC7,$B$44:$C$52,2) -> F | AE7: 23 | AF7: 38 | AG7: =AE7+AF7 -> 61 | AH7: =VLOOKUP(AG7,$B$44:$C$52,2) -> C | AI7: 24 | AJ7: 42 | AK7: =AI7+AJ7 -> 66 | AL7: =VLOOKUP(AK7,$B$44:$C$52,2) -> C | AM7: 20 | AN7: 44 | AO7: =AM7+AN7 -> 64 | AP7: =VLOOKUP(AO7,$B$44:$C$52,2) -> C | AR7: =AVERAGE(E7,I7,M7,Q7,U7,Y7,AC7,AG7,AK7,AO7) -> 42.8 | AS7: =RANK(AR7,$AR$5:$AR$33) -> 24 | AT7: C | AU7: D | AV7: D | AW7: C | AX7: D | AY7: Mohammed shows average behaviour and finds it difficult to sit still for long periods, often becoming distracted by friends. Despite this, his academic performance is very good. To improve further, he should work on managing distractions and developing better concentration habits. Sitting in a quiet area and following structured study routines will help him stay focused. Mohammed is encouraged to continue working hard while improving his behaviour.
A8: 4 | B8: Munshi Khadijah | C8: 26 | D8: 54 | E8: =C8+D8 -> 80 | F8: =VLOOKUP(E8,$B$44:$C$52,2) -> A | G8: 7 | H8: 10 | I8: =G8+H8 -> 17 | J8: =VLOOKUP(I8,$B$44:$C$52,2) -> U | K8: 14 | L8: 29 | M8: =K8+L8 -> 43 | N8: =VLOOKUP(M8,$B$44:$C$52,2) -> E | O8: 31 | P8: 24 | Q8: =O8+P8 -> 55 | R8: =VLOOKUP(Q8,$B$44:$C$52,2) -> D | S8: 20 | T8: 36 | U8: =S8+T8 -> 56 | V8: =VLOOKUP(U8,$B$44:$C$52,2) -> D | W8: 32 | X8: 24 | Y8: =W8+X8 -> 56 | Z8: =VLOOKUP(Y8,$B$44:$C$52,2) -> D | AA8: 14 | AB8: 34 | AC8: =AA8+AB8 -> 48 | AD8: =VLOOKUP(AC8,$B$44:$C$52,2) -> E | AE8: 32 | AF8: 48 | AG8: =AE8+AF8 -> 80 | AH8: =VLOOKUP(AG8,$B$44:$C$52,2) -> A | AI8: 32 | AJ8: 42 | AK8: =AI8+AJ8 -> 74 | AL8: =VLOOKUP(AK8,$B$44:$C$52,2) -> B | AM8: 22.5 | AN8: 49 | AO8: =AM8+AN8 -> 71.5 | AP8: =VLOOKUP(AO8,$B$44:$C$52,2) -> B | AR8: =AVERAGE(E8,I8,M8,Q8,U8,Y8,AC8,AG8,AK8,AO8) -> 58.05 | AS8: =RANK(AR8,$AR$5:$AR$33) -> 17 | AT8: B | AU8: B | AV8: B | AW8: C | AX8: B | AY8: Khadijah demonstrates very good behaviour and a positive attitude towards learning. Her academic performance is good and shows clear potential for further growth. She can improve by taking more initiative in challenging tasks and deepening her understanding through wider reading. Maintaining consistent study habits will support her progress. I encourage Khadijah to continue her strong effort and stay committed to excellence.
A9: 5 | B9: Mwewa Likezo | C9: 25 | D9: 20 | E9: =C9+D9 -> 45 | F9: =VLOOKUP(E9,$B$44:$C$52,2) -> E | G9: 5 | H9: 13 | I9: =G9+H9 -> 18 | J9: =VLOOKUP(I9,$B$44:$C$52,2) -> U | K9: 11 | L9: 17 | M9: =K9+L9 -> 28 | N9: =VLOOKUP(M9,$B$44:$C$52,2) -> G | O9: 26 | P9: 31 | Q9: =O9+P9 -> 57 | R9: =VLOOKUP(Q9,$B$44:$C$52,2) -> D | S9: 19 | T9: 36 | U9: =S9+T9 -> 55 | V9: =VLOOKUP(U9,$B$44:$C$52,2) -> D | W9: 30 | X9: 37 | Y9: =W9+X9 -> 67 | Z9: =VLOOKUP(Y9,$B$44:$C$52,2) -> C | AA9: 17 | AB9: 29 | AC9: =AA9+AB9 -> 46 | AD9: =VLOOKUP(AC9,$B$44:$C$52,2) -> E | AE9: 24 | AF9: 39 | AG9: =AE9+AF9 -> 63 | AH9: =VLOOKUP(AG9,$B$44:$C$52,2) -> C | AI9: 29 | AJ9: 42 | AK9: =AI9+AJ9 -> 71 | AL9: =VLOOKUP(AK9,$B$44:$C$52,2) -> B | AM9: 16.7 | AN9: 25 | AO9: =AM9+AN9 -> 41.7 | AP9: =VLOOKUP(AO9,$B$44:$C$52,2) -> E | AR9: =AVERAGE(E9,I9,M9,Q9,U9,Y9,AC9,AG9,AK9,AO9) -> 49.17 | AS9: =RANK(AR9,$AR$5:$AR$33) -> 22 | AT9: A | AU9: A | AV9: C | AW9: C | AX9: B | AY9: Likezo behaves well but struggles to stay focused for long periods and often isolates himself. He needs improvement in Science, Maths, and English. Developing better engagement in class and participating more actively will support his progress. Completing regular practice at home and reviewing lessons will help strengthen his understanding. I encourage Likezo to interact more
A10: 6 | B10: Blount Jaxen | C10: 28 | D10: 42 | E10: =C10+D10 -> 70 | F10: =VLOOKUP(E10,$B$44:$C$52,2) -> B | G10: 8 | H10: 30 | I10: =G10+H10 -> 38 | J10: =VLOOKUP(I10,$B$44:$C$52,2) -> F | K10: 10 | L10: 35 | M10: =K10+L10 -> 45 | N10: =VLOOKUP(M10,$B$44:$C$52,2) -> E | O10: 31 | P10: 47 | Q10: =O10+P10 -> 78 | R10: =VLOOKUP(Q10,$B$44:$C$52,2) -> B | S10: 22 | T10: 36 | U10: =S10+T10 -> 58 | V10: =VLOOKUP(U10,$B$44:$C$52,2) -> D | W10: 23 | X10: 31 | Y10: =W10+X10 -> 54 | Z10: =VLOOKUP(Y10,$B$44:$C$52,2) -> D | AA10: 13 | AB10: 35 | AC10: =AA10+AB10 -> 48 | AD10: =VLOOKUP(AC10,$B$44:$C$52,2) -> E | AE10: 25 | AF10: 47 | AG10: =AE10+AF10 -> 72 | AH10: =VLOOKUP(AG10,$B$44:$C$52,2) -> B | AI10: 30 | AJ10: 51 | AK10: =AI10+AJ10 -> 81 | AL10: =VLOOKUP(AK10,$B$44:$C$52,2) -> A | AM10: 21 | AN10: 39 | AO10: =AM10+AN10 -> 60 | AP10: =VLOOKUP(AO10,$B$44:$C$52,2) -> C | AR10: =AVERAGE(E10,I10,M10,Q10,U10,Y10,AC10,AG10,AK10,AO10) -> 60.4 | AS10: =RANK(AR10,$AR$5:$AR$33) -> 14 | AT10: A+ | AU10: C | AV10: C | AW10: C | AX10: C | AY10: Jaxen displays average behaviour and often loses focus, becoming easily distracted. His performance in Science, Maths, and English needs improvement. I would also like to acknowledge his effort and confidence in presenting at TEDx, which is a commendable achievement. He should practise staying attentive in class and completing tasks without rushing. Regular revision, extra exercises, and asking for help when needed will support his progress. Improving his study routines and reducing distractions will greatly benefit him. With consistent effort and a more focused approach, Jaxen has the potential to achieve much stronger results.
A11: 7 | B11: Shamiso | C11: 27 | D11: 37 | E11: =C11+D11 -> 64 | F11: =VLOOKUP(E11,$B$44:$C$52,2) -> C | G11: 15 | H11: 36 | I11: =G11+H11 -> 51 | J11: =VLOOKUP(I11,$B$44:$C$52,2) -> D | K11: 12 | L11: 30 | M11: =K11+L11 -> 42 | N11: =VLOOKUP(M11,$B$44:$C$52,2) -> E | O11: 28 | P11: 47 | Q11: =O11+P11 -> 75 | R11: =VLOOKUP(Q11,$B$44:$C$52,2) -> B | S11: 18 | T11: 43 | U11: =S11+T11 -> 61 | V11: =VLOOKUP(U11,$B$44:$C$52,2) -> C | W11: 23 | X11: 31 | Y11: =W11+X11 -> 54 | Z11: =VLOOKUP(Y11,$B$44:$C$52,2) -> D | AA11: 18 | AB11: 41 | AC11: =AA11+AB11 -> 59 | AD11: =VLOOKUP(AC11,$B$44:$C$52,2) -> D | AE11: 30 | AF11: 46 | AG11: =AE11+AF11 -> 76 | AH11: =VLOOKUP(AG11,$B$44:$C$52,2) -> B | AI11: 31 | AJ11: 48 | AK11: =AI11+AJ11 -> 79 | AL11: =VLOOKUP(AK11,$B$44:$C$52,2) -> B | AM11: 33.5 | AN11: 50 | AO11: =AM11+AN11 -> 83.5 | AP11: =VLOOKUP(AO11,$B$44:$C$52,2) -> A | AR11: =AVERAGE(E11,I11,M11,Q11,U11,Y11,AC11,AG11,AK11,AO11) -> 64.45 | AS11: =RANK(AR11,$AR$5:$AR$33) -> 12 | AT11: C | AU11: A | AV11: C | AW11: A | AX11: A | AY11: Shamiso behaves well and participates positively in class. However, she needs to improve in Science, Maths, and English. Paying close attention during lessons and completing extra practice will help her strengthen her skills. Asking questions when unsure and revising daily will support her learning. I encourage her to remain focused and dedicated. With consistent effort, Shamiso can make great progress.
A12: 8 | B12: Mwansa Louise Elizabeth | C12: 29 | D12: 41 | E12: =C12+D12 -> 70 | F12: =VLOOKUP(E12,$B$44:$C$52,2) -> B | G12: 15 | H12: 22 | I12: =G12+H12 -> 37 | J12: =VLOOKUP(I12,$B$44:$C$52,2) -> F | K12: 23 | L12: 31 | M12: =K12+L12 -> 54 | N12: =VLOOKUP(M12,$B$44:$C$52,2) -> D | O12: 29 | P12: 37 | Q12: =O12+P12 -> 66 | R12: =VLOOKUP(Q12,$B$44:$C$52,2) -> C | S12: 23 | T12: 38 | U12: =S12+T12 -> 61 | V12: =VLOOKUP(U12,$B$44:$C$52,2) -> C | W12: 33 | X12: 35 | Y12: =W12+X12 -> 68 | Z12: =VLOOKUP(Y12,$B$44:$C$52,2) -> C | AA12: 30 | AB12: 44 | AC12: =AA12+AB12 -> 74 | AD12: =VLOOKUP(AC12,$B$44:$C$52,2) -> B | AE12: 36 | AF12: 53 | AG12: =AE12+AF12 -> 89 | AH12: =VLOOKUP(AG12,$B$44:$C$52,2) -> A | AI12: 33 | AJ12: 41 | AK12: =AI12+AJ12 -> 74 | AL12: =VLOOKUP(AK12,$B$44:$C$52,2) -> B | AM12: 25.6 | AN12: 49 | AO12: =AM12+AN12 -> 74.6 | AP12: =VLOOKUP(AO12,$B$44:$C$52,2) -> B | AR12: =AVERAGE(E12,I12,M12,Q12,U12,Y12,AC12,AG12,AK12,AO12) -> 66.76 | AS12: =RANK(AR12,$AR$5:$AR$33) -> 10 | AT12: C | AU12: C | AV12: C | AW12: C | AX12: D | AY12: Louise displays average behaviour and often moves around a lot, which affects her concentration. She needs improvement in Science, Maths, and English. Staying focused in class and reducing unnecessary movement will help improve her understanding. Regular practice at home and revising key concepts will support her progress. With greater focus and discipline, Louise can achieve stronger academic results. I encourage her to stay motivated and committed.
A13: 9 | B13: Patel Maahir | C13: 23 | D13: 30 | E13: =C13+D13 -> 53 | F13: =VLOOKUP(E13,$B$44:$C$52,2) -> D | G13: 26 | H13: 43 | I13: =G13+H13 -> 69 | J13: =VLOOKUP(I13,$B$44:$C$52,2) -> C | K13: 34 | L13: 40 | M13: =K13+L13 -> 74 | N13: =VLOOKUP(M13,$B$44:$C$52,2) -> B | O13: 26 | P13: 42 | Q13: =O13+P13 -> 68 | R13: =VLOOKUP(Q13,$B$44:$C$52,2) -> C | S13: 30 | T13: 50 | U13: =S13+T13 -> 80 | V13: =VLOOKUP(U13,$B$44:$C$52,2) -> A | W13: 37 | X13: 46 | Y13: =W13+X13 -> 83 | Z13: =VLOOKUP(Y13,$B$44:$C$52,2) -> A | AA13: 31 | AB13: 52 | AC13: =AA13+AB13 -> 83 | AD13: =VLOOKUP(AC13,$B$44:$C$52,2) -> A | AE13: 28 | AF13: 54 | AG13: =AE13+AF13 -> 82 | AH13: =VLOOKUP(AG13,$B$44:$C$52,2) -> A | AI13: 30 | AJ13: 51 | AK13: =AI13+AJ13 -> 81 | AL13: =VLOOKUP(AK13,$B$44:$C$52,2) -> A | AM13: 24.9 | AN13: 38 | AO13: =AM13+AN13 -> 62.9 | AP13: =VLOOKUP(AO13,$B$44:$C$52,2) -> C | AR13: =AVERAGE(E13,I13,M13,Q13,U13,Y13,AC13,AG13,AK13,AO13) -> 73.59 | AS13: =RANK(AR13,$AR$5:$AR$33) -> 6 | AT13: A | AU13: A+ | AV13: C | AW13: C | AX13: B | AY13: Maahir demonstrates excellent behaviour and consistently shows a positive attitude towards learning. His academic performance is very strong across all subjects. To extend his skills further, he should continue exploring challenging tasks and developing independent study habits. Engaging confidently in discussions will enrich his learning. Maahir is encouraged to maintain his outstanding effort and continue striving for excellence.
A14: 10 | B14: Aloyo Viola | C14: 26 | D14: 33 | E14: =C14+D14 -> 59 | F14: =VLOOKUP(E14,$B$44:$C$52,2) -> D | G14: 8 | H14: 16 | I14: =G14+H14 -> 24 | J14: =VLOOKUP(I14,$B$44:$C$52,2) -> G | K14: 18 | L14: 28 | M14: =K14+L14 -> 46 | N14: =VLOOKUP(M14,$B$44:$C$52,2) -> E | O14: 25 | P14: 27 | Q14: =O14+P14 -> 52 | R14: =VLOOKUP(Q14,$B$44:$C$52,2) -> D | S14: 17 | T14: 37 | U14: =S14+T14 -> 54 | V14: =VLOOKUP(U14,$B$44:$C$52,2) -> D | W14: 21 | X14: 33 | Y14: =W14+X14 -> 54 | Z14: =VLOOKUP(Y14,$B$44:$C$52,2) -> D | AA14: 11 | AB14: 42 | AC14: =AA14+AB14 -> 53 | AD14: =VLOOKUP(AC14,$B$44:$C$52,2) -> D | AE14: 26 | AF14: 40 | AG14: =AE14+AF14 -> 66 | AH14: =VLOOKUP(AG14,$B$44:$C$52,2) -> C | AI14: 30 | AJ14: 43 | AK14: =AI14+AJ14 -> 73 | AL14: =VLOOKUP(AK14,$B$44:$C$52,2) -> B | AM14: 19.5 | AN14: 35 | AO14: =AM14+AN14 -> 54.5 | AP14: =VLOOKUP(AO14,$B$44:$C$52,2) -> D | AR14: =AVERAGE(E14,I14,M14,Q14,U14,Y14,AC14,AG14,AK14,AO14) -> 53.55 | AS14: =RANK(AR14,$AR$5:$AR$33) -> 21 | AT14: C | AU14: C | AV14: C | AW14: C | AX14: C | AY14: Viola maintains good behaviour and shows willingness to learn. She needs improvement in Science, Maths, and English. Strengthening her focus and completing tasks carefully will support her progress in these subjects. Regular revision and independent practice at home will help build confidence. I encourage her to keep working hard and stay dedicated. With determination, Viola can achieve better results.
A15: 11 | B15: Mohamed Moaz | C15: 16 | D15: 14 | E15: =C15+D15 -> 30 | F15: =VLOOKUP(E15,$B$44:$C$52,2) -> F | G15: 15 | H15: 17 | I15: =G15+H15 -> 32 | J15: =VLOOKUP(I15,$B$44:$C$52,2) -> F | K15: 19 | L15: 23 | M15: =K15+L15 -> 42 | N15: =VLOOKUP(M15,$B$44:$C$52,2) -> E | O15: 19 | P15: 16 | Q15: =O15+P15 -> 35 | R15: =VLOOKUP(Q15,$B$44:$C$52,2) -> F | S15: 17 | T15: 26 | U15: =S15+T15 -> 43 | V15: =VLOOKUP(U15,$B$44:$C$52,2) -> E | W15: 22 | X15: 30 | Y15: =W15+X15 -> 52 | Z15: =VLOOKUP(Y15,$B$44:$C$52,2) -> D | AA15: 12 | AB15: 19 | AC15: =AA15+AB15 -> 31 | AD15: =VLOOKUP(AC15,$B$44:$C$52,2) -> F | AE15: 27 | AF15: 54 | AG15: =AE15+AF15 -> 81 | AH15: =VLOOKUP(AG15,$B$44:$C$52,2) -> A | AI15: 25 | AJ15: 40 | AK15: =AI15+AJ15 -> 65 | AL15: =VLOOKUP(AK15,$B$44:$C$52,2) -> C | AM15: 24.9 | AN15: 46 | AO15: =AM15+AN15 -> 70.9 | AP15: =VLOOKUP(AO15,$B$44:$C$52,2) -> B | AR15: =AVERAGE(E15,I15,M15,Q15,U15,Y15,AC15,AG15,AK15,AO15) -> 48.19 | AS15: =RANK(AR15,$AR$5:$AR$33) -> 23 | AT15: C | AU15: C | AV15: C | AW15: C | AX15: C | AY15: Moaz is generally well-behaved and interacts positively with others. His performance in Science, Maths, and English needs improvement. Staying attentive, participating more actively, and completing all class tasks will support his academic development. Additional practice at home and reviewing lessons will strengthen his understanding. Moaz is encouraged to remain motivated and take responsibility for his learning. With effort, he can achieve steady improvement.
A16: 12 | B16: Mutonga Israel | C16: 21 | D16: 34 | E16: =C16+D16 -> 55 | F16: =VLOOKUP(E16,$B$44:$C$52,2) -> D | G16: 7 | H16: 19 | I16: =G16+H16 -> 26 | J16: =VLOOKUP(I16,$B$44:$C$52,2) -> G | K16: 14 | L16: 24 | M16: =K16+L16 -> 38 | N16: =VLOOKUP(M16,$B$44:$C$52,2) -> F | O16: 32 | P16: 41 | Q16: =O16+P16 -> 73 | R16: =VLOOKUP(Q16,$B$44:$C$52,2) -> B | S16: 28 | T16: 40 | U16: =S16+T16 -> 68 | V16: =VLOOKUP(U16,$B$44:$C$52,2) -> C | W16: 24 | X16: 36 | Y16: =W16+X16 -> 60 | Z16: =VLOOKUP(Y16,$B$44:$C$52,2) -> C | AA16: 20 | AB16: 28 | AC16: =AA16+AB16 -> 48 | AD16: =VLOOKUP(AC16,$B$44:$C$52,2) -> E | AE16: 29 | AF16: 45 | AG16: =AE16+AF16 -> 74 | AH16: =VLOOKUP(AG16,$B$44:$C$52,2) -> B | AI16: 31 | AJ16: 35 | AK16: =AI16+AJ16 -> 66 | AL16: =VLOOKUP(AK16,$B$44:$C$52,2) -> C | AM16: 24.7 | AN16: 48 | AO16: =AM16+AN16 -> 72.7 | AP16: =VLOOKUP(AO16,$B$44:$C$52,2) -> B | AR16: =AVERAGE(E16,I16,M16,Q16,U16,Y16,AC16,AG16,AK16,AO16) -> 58.07 | AS16: =RANK(AR16,$AR$5:$AR$33) -> 16 | AT16: C | AU16: B | AV16: C | AW16: C | AX16: C | AY16: Israel behaves well overall but becomes easily distracted, which affects his performance. He needs to improve in Science, Maths, and English. Staying focused during lessons and managing distractions will greatly help his learning. Extra practice at home, reading regularly, and revising daily will support improvement. Israel is encouraged to participate more actively and ask questions for clarity. With consistent effort, he can make strong academic progress.
A17: 13 | B17: Abdulle Abdullahi | C17: 22 | D17: 31 | E17: =C17+D17 -> 53 | F17: =VLOOKUP(E17,$B$44:$C$52,2) -> D | G17: 19 | H17: 33 | I17: =G17+H17 -> 52 | J17: =VLOOKUP(I17,$B$44:$C$52,2) -> D | K17: 28 | L17: 38 | M17: =K17+L17 -> 66 | N17: =VLOOKUP(M17,$B$44:$C$52,2) -> C | O17: 26 | P17: 29 | Q17: =O17+P17 -> 55 | R17: =VLOOKUP(Q17,$B$44:$C$52,2) -> D | S17: 17 | T17: 33 | U17: =S17+T17 -> 50 | V17: =VLOOKUP(U17,$B$44:$C$52,2) -> D | W17: 27 | X17: 32 | Y17: 59 | Z17: =VLOOKUP(Y17,$B$44:$C$52,2) -> D | AA17: 18 | AB17: 31 | AC17: =AA17+AB17 -> 49 | AD17: =VLOOKUP(AC17,$B$44:$C$52,2) -> E | AE17: 22 | AF17: 32 | AG17: =AE17+AF17 -> 54 | AH17: =VLOOKUP(AG17,$B$44:$C$52,2) -> D | AI17: 27 | AJ17: 43 | AK17: =AI17+AJ17 -> 70 | AL17: =VLOOKUP(AK17,$B$44:$C$52,2) -> B | AM17: 24.7 | AN17: 46 | AO17: =AM17+AN17 -> 70.7 | AP17: =VLOOKUP(AO17,$B$44:$C$52,2) -> B | AR17: =AVERAGE(E17,I17,M17,Q17,U17,Y17,AC17,AG17,AK17,AO17) -> 57.87 | AS17: =RANK(AR17,$AR$5:$AR$33) -> 18 | AT17: C | AU17: C | AV17: C | AW17: C | AX17: A | AY17: Abdullahi is a polite and well-behaved learner who engages positively in class activities. His academic performance shows potential, but he needs to put in more consistent effort to achieve better results. He would benefit from improving his concentration during lessons and completing tasks with greater care. Regular revision at home and seeking clarification when unsure will support his progress. I encourage him to remain committed and to stay focused during class. With steady effort, Abdullahi can make significant improvement.
A18: 14 | B18: Sillitoe Alan | C18: 32 | D18: 40 | E18: =C18+D18 -> 72 | F18: =VLOOKUP(E18,$B$44:$C$52,2) -> B | G18: 18 | H18: 27 | I18: =G18+H18 -> 45 | J18: =VLOOKUP(I18,$B$44:$C$52,2) -> E | K18: 19 | L18: 36 | M18: =K18+L18 -> 55 | N18: =VLOOKUP(M18,$B$44:$C$52,2) -> D | O18: 32 | P18: 50 | Q18: =O18+P18 -> 82 | R18: =VLOOKUP(Q18,$B$44:$C$52,2) -> A | S18: 29 | T18: 43 | U18: =S18+T18 -> 72 | V18: =VLOOKUP(U18,$B$44:$C$52,2) -> B | W18: 30 | X18: 37 | Y18: =W18+X18 -> 67 | Z18: =VLOOKUP(Y18,$B$44:$C$52,2) -> C | AA18: 17 | AB18: 20 | AC18: =AA18+AB18 -> 37 | AD18: =VLOOKUP(AC18,$B$44:$C$52,2) -> F | AE18: 29 | AF18: 44 | AG18: =AE18+AF18 -> 73 | AH18: =VLOOKUP(AG18,$B$44:$C$52,2) -> B | AI18: 31 | AJ18: 40 | AK18: =AI18+AJ18 -> 71 | AL18: =VLOOKUP(AK18,$B$44:$C$52,2) -> B | AM18: 26 | AN18: 47 | AO18: =AM18+AN18 -> 73 | AP18: =VLOOKUP(AO18,$B$44:$C$52,2) -> B | AR18: =AVERAGE(E18,I18,M18,Q18,U18,Y18,AC18,AG18,AK18,AO18) -> 64.7 | AS18: =RANK(AR18,$AR$5:$AR$33) -> 11 | AT18: C | AU18: B | AV18: C | AW18: C | AX18: B | AY18: Aaban behaves reasonably well but is easily distracted, which affects his concentration in class. His academic performance is good when he remains focused. He needs to work on minimising distractions and staying engaged throughout lessons. Using short study routines and sitting away from distractions will support his progress. With improved concentration, Aaban can achieve even better results. I encourage him to stay committed and focused.
A19: 15 | B19: Kaoma Natasha | C19: 37 | D19: 48 | E19: =C19+D19 -> 85 | F19: =VLOOKUP(E19,$B$44:$C$52,2) -> A | G19: 24 | H19: 45 | I19: =G19+H19 -> 69 | J19: =VLOOKUP(I19,$B$44:$C$52,2) -> C | K19: 32 | L19: 50 | M19: =K19+L19 -> 82 | N19: =VLOOKUP(M19,$B$44:$C$52,2) -> A | O19: 33 | P19: 53 | Q19: =O19+P19 -> 86 | R19: =VLOOKUP(Q19,$B$44:$C$52,2) -> A | S19: 26 | T19: 45 | U19: =S19+T19 -> 71 | V19: =VLOOKUP(U19,$B$44:$C$52,2) -> B | W19: 40 | X19: 35 | Y19: =W19+X19 -> 75 | Z19: =VLOOKUP(Y19,$B$44:$C$52,2) -> B | AA19: 35 | AB19: 49 | AC19: =AA19+AB19 -> 84 | AD19: =VLOOKUP(AC19,$B$44:$C$52,2) -> A | AE19: 32 | AF19: 52 | AG19: =AE19+AF19 -> 84 | AH19: =VLOOKUP(AG19,$B$44:$C$52,2) -> A | AI19: 33 | AJ19: 54 | AK19: =AI19+AJ19 -> 87 | AL19: =VLOOKUP(AK19,$B$44:$C$52,2) -> A | AM19: 23.7 | AN19: 49 | AO19: =AM19+AN19 -> 72.7 | AP19: =VLOOKUP(AO19,$B$44:$C$52,2) -> B | AR19: =AVERAGE(E19,I19,M19,Q19,U19,Y19,AC19,AG19,AK19,AO19) -> 79.57 | AS19: =RANK(AR19,$AR$5:$AR$33) -> 2 | AT19: C | AU19: B | AV19: C | AW19: C | AX19: B | AY19: Natasha is a very well-behaved student who always sets a positive example for others. Her academic performance is excellent, and she shows great commitment to her studies. To extend her abilities further, she should continue challenging herself with higher-level tasks. Continued reading and independent study will help deepen her knowledge. Natasha is encouraged to maintain her outstanding attitude and keep striving for excellence.
A20: 16 | B20: Chauhan Humera | C20: 30 | D20: 42 | E20: =C20+D20 -> 72 | F20: =VLOOKUP(E20,$B$44:$C$52,2) -> B | G20: 19 | H20: 38 | I20: =G20+H20 -> 57 | J20: =VLOOKUP(I20,$B$44:$C$52,2) -> D | K20: 26 | L20: 43 | M20: =K20+L20 -> 69 | N20: =VLOOKUP(M20,$B$44:$C$52,2) -> C | O20: 34 | P20: 49 | Q20: =O20+P20 -> 83 | R20: =VLOOKUP(Q20,$B$44:$C$52,2) -> A | S20: 32 | T20: 51 | U20: =S20+T20 -> 83 | V20: =VLOOKUP(U20,$B$44:$C$52,2) -> A | W20: 40 | X20: 52 | Y20: =W20+X20 -> 92 | Z20: =VLOOKUP(Y20,$B$44:$C$52,2) -> A* | AA20: 30 | AB20: 49 | AC20: =AA20+AB20 -> 79 | AD20: =VLOOKUP(AC20,$B$44:$C$52,2) -> B | AE20: 28 | AF20: 46 | AG20: =AE20+AF20 -> 74 | AH20: =VLOOKUP(AG20,$B$44:$C$52,2) -> B | AI20: 31 | AJ20: 54 | AK20: =AI20+AJ20 -> 85 | AL20: =VLOOKUP(AK20,$B$44:$C$52,2) -> A | AM20: 22.5 | AN20: 48 | AO20: =AM20+AN20 -> 70.5 | AP20: =VLOOKUP(AO20,$B$44:$C$52,2) -> B | AR20: =AVERAGE(E20,I20,M20,Q20,U20,Y20,AC20,AG20,AK20,AO20) -> 76.45 | AS20: =RANK(AR20,$AR$5:$AR$33) -> 4 | AT20: C | AU20: B | AV20: C | AW20: C | AX20: A | AY20: Humera maintains good behaviour and displays a positive attitude towards learning. Her academic performance is strong, and she consistently produces good work. I would also like to commend her for confidently presenting at TEDx, a remarkable achievement that reflects her dedication and courage. To reach even higher levels, she should continue building her confidence in class discussions and challenge herself with extended tasks. Maintaining her current study habits and practising regular revision will help her excel. I encourage Humera to keep up her excellent attitude and continue striving for excellence.
A21: 17 | B21: Ntinda Joy | C21: 31 | D21: 31 | E21: =C21+D21 -> 62 | F21: =VLOOKUP(E21,$B$44:$C$52,2) -> C | G21: 16 | H21: 42 | I21: =G21+H21 -> 58 | J21: =VLOOKUP(I21,$B$44:$C$52,2) -> D | K21: 9 | L21: 25 | M21: =K21+L21 -> 34 | N21: =VLOOKUP(M21,$B$44:$C$52,2) -> F | O21: 28 | P21: 36 | Q21: =O21+P21 -> 64 | R21: =VLOOKUP(Q21,$B$44:$C$52,2) -> C | S21: 25 | T21: 34 | U21: =S21+T21 -> 59 | V21: =VLOOKUP(U21,$B$44:$C$52,2) -> D | W21: 16 | X21: 23 | Y21: =W21+X21 -> 39 | Z21: =VLOOKUP(Y21,$B$44:$C$52,2) -> F | AA21: 14 | AB21: 32 | AC21: =AA21+AB21 -> 46 | AD21: =VLOOKUP(AC21,$B$44:$C$52,2) -> E | AE21: 27 | AF21: 47 | AG21: =AE21+AF21 -> 74 | AH21: =VLOOKUP(AG21,$B$44:$C$52,2) -> B | AI21: 27 | AJ21: 41 | AK21: =AI21+AJ21 -> 68 | AL21: =VLOOKUP(AK21,$B$44:$C$52,2) -> C | AM21: 27 | AN21: 54 | AO21: =AM21+AN21 -> 81 | AP21: =VLOOKUP(AO21,$B$44:$C$52,2) -> A | AR21: =AVERAGE(E21,I21,M21,Q21,U21,Y21,AC21,AG21,AK21,AO21) -> 58.5 | AS21: =RANK(AR21,$AR$5:$AR$33) -> 15 | AT21: C | AU21: C | AV21: C | AW21: C | AX21: C | AY21: Joy shows average behaviour and often moves around unnecessarily, which affects her focus. She needs to improve in Science, Maths, and English. Staying seated, listening attentively, and following instructions will help her concentrate better. Regular revision and practising core skills at home will support her learning. With improved discipline and commitment, Joy can achieve much stronger results. I encourage her to keep trying and stay motivated.
A22: 18 | B22: Msoni Zhange | C22: 33 | D22: 40 | E22: =C22+D22 -> 73 | F22: =VLOOKUP(E22,$B$44:$C$52,2) -> B | G22: 5 | H22: 20 | I22: =G22+H22 -> 25 | J22: =VLOOKUP(I22,$B$44:$C$52,2) -> G | K22: 12 | L22: 23 | M22: =K22+L22 -> 35 | N22: =VLOOKUP(M22,$B$44:$C$52,2) -> F | O22: 26 | P22: 49 | Q22: =O22+P22 -> 75 | R22: =VLOOKUP(Q22,$B$44:$C$52,2) -> B | S22: 27 | T22: 37 | U22: =S22+T22 -> 64 | V22: =VLOOKUP(U22,$B$44:$C$52,2) -> C | W22: 28 | X22: 26 | Y22: =W22+X22 -> 54 | Z22: =VLOOKUP(Y22,$B$44:$C$52,2) -> D | AA22: 20 | AB22: 41 | AC22: =AA22+AB22 -> 61 | AD22: =VLOOKUP(AC22,$B$44:$C$52,2) -> C | AE22: 25 | AF22: 38 | AG22: =AE22+AF22 -> 63 | AH22: =VLOOKUP(AG22,$B$44:$C$52,2) -> C | AI22: 32 | AJ22: 41 | AK22: =AI22+AJ22 -> 73 | AL22: =VLOOKUP(AK22,$B$44:$C$52,2) -> B | AM22: 20.8 | AN22: 24 | AO22: =AM22+AN22 -> 44.8 | AP22: =VLOOKUP(AO22,$B$44:$C$52,2) -> E | AR22: =AVERAGE(E22,I22,M22,Q22,U22,Y22,AC22,AG22,AK22,AO22) -> 56.78 | AS22: =RANK(AR22,$AR$5:$AR$33) -> 19 | AT22: C | AU22: B | AV22: C | AW22: C | AX22: B | AY22: Zhange is generally well-behaved and polite. However, she needs to improve her performance in Science, Maths, and English. She would benefit from developing better focus during lessons and practising regularly at home. Using additional learning materials and reviewing class notes will help strengthen her understanding. I encourage Zhange to stay motivated and seek support whenever needed. With determination, she can make steady progress.
A23: 19 | B23: Nalishuwa Zeruiah | C23: 28 | D23: 41 | E23: =C23+D23 -> 69 | F23: =VLOOKUP(E23,$B$44:$C$52,2) -> C | G23: 24 | H23: 38 | I23: =G23+H23 -> 62 | J23: =VLOOKUP(I23,$B$44:$C$52,2) -> C | K23: 30 | L23: 26 | M23: =K23+L23 -> 56 | N23: =VLOOKUP(M23,$B$44:$C$52,2) -> D | O23: 34 | P23: 46 | Q23: =O23+P23 -> 80 | R23: =VLOOKUP(Q23,$B$44:$C$52,2) -> A | S23: 27 | T23: 42 | U23: =S23+T23 -> 69 | V23: =VLOOKUP(U23,$B$44:$C$52,2) -> C | W23: 40 | X23: 36 | Y23: =W23+X23 -> 76 | Z23: =VLOOKUP(Y23,$B$44:$C$52,2) -> B | AA23: 23 | AB23: 44 | AC23: =AA23+AB23 -> 67 | AD23: =VLOOKUP(AC23,$B$44:$C$52,2) -> C | AE23: 26 | AF23: 50 | AG23: =AE23+AF23 -> 76 | AH23: =VLOOKUP(AG23,$B$44:$C$52,2) -> B | AI23: 33 | AJ23: 50 | AK23: =AI23+AJ23 -> 83 | AL23: =VLOOKUP(AK23,$B$44:$C$52,2) -> A | AM23: 28 | AN23: 47 | AO23: =AM23+AN23 -> 75 | AP23: =VLOOKUP(AO23,$B$44:$C$52,2) -> B | AR23: =AVERAGE(E23,I23,M23,Q23,U23,Y23,AC23,AG23,AK23,AO23) -> 71.3 | AS23: =RANK(AR23,$AR$5:$AR$33) -> 7 | AT23: B | AU23: B | AV23: C | AW23: C | AX23: A | AY23: Zeruiah is a very well-behaved learner who consistently shows a positive attitude. Her academic performance is good, and she completes tasks to a high standard. To develop further, she should continue challenging herself with extension activities and practising independent study. Regular reading will also strengthen her skills. Zeruiah is encouraged to maintain her excellent attitude and continue striving for success.
A24: 20 | B24: Shalak Jad | C24: 27 | D24: 39 | E24: =C24+D24 -> 66 | F24: =VLOOKUP(E24,$B$44:$C$52,2) -> C | G24: 32 | H24: 48 | I24: =G24+H24 -> 80 | J24: =VLOOKUP(I24,$B$44:$C$52,2) -> A | K24: 26 | L24: 43 | M24: =K24+L24 -> 69 | N24: =VLOOKUP(M24,$B$44:$C$52,2) -> C | O24: 30 | P24: 43 | Q24: =O24+P24 -> 73 | R24: =VLOOKUP(Q24,$B$44:$C$52,2) -> B | S24: 37 | T24: 49 | U24: =S24+T24 -> 86 | V24: =VLOOKUP(U24,$B$44:$C$52,2) -> A | W24: 40 | X24: 54 | Y24: =W24+X24 -> 94 | Z24: =VLOOKUP(Y24,$B$44:$C$52,2) -> A* | AA24: 34 | AB24: 52 | AC24: =AA24+AB24 -> 86 | AD24: =VLOOKUP(AC24,$B$44:$C$52,2) -> A | AE24: 26 | AF24: 46 | AG24: =AE24+AF24 -> 72 | AH24: =VLOOKUP(AG24,$B$44:$C$52,2) -> B | AI24: 32 | AJ24: 54 | AK24: =AI24+AJ24 -> 86 | AL24: =VLOOKUP(AK24,$B$44:$C$52,2) -> A | AM24: 25 | AN24: 38 | AO24: =AM24+AN24 -> 63 | AP24: =VLOOKUP(AO24,$B$44:$C$52,2) -> C | AR24: =AVERAGE(E24,I24,M24,Q24,U24,Y24,AC24,AG24,AK24,AO24) -> 77.5 | AS24: =RANK(AR24,$AR$5:$AR$33) -> 3 | AT24: A | AU24: A+ | AV24: B | AW24: C | AX24: A | AY24: Jad consistently demonstrates very good behaviour and enthusiasm for learning. His academic performance is very strong across subjects. To further enrich his learning, he should continue developing his critical-thinking skills through independent tasks and wider reading. Participating even more confidently in class discussions will also benefit him. Jad is encouraged to maintain his high standards and keep up his excellent work.
A25: 21 | B25: Nyirenda Lauzi | C25: 27 | D25: 30 | E25: =C25+D25 -> 57 | F25: =VLOOKUP(E25,$B$44:$C$52,2) -> D | G25: 7 | H25: 25 | I25: =G25+H25 -> 32 | J25: =VLOOKUP(I25,$B$44:$C$52,2) -> F | K25: 18 | L25: 31 | M25: =K25+L25 -> 49 | N25: =VLOOKUP(M25,$B$44:$C$52,2) -> E | O25: 26 | P25: 56 | Q25: =O25+P25 -> 82 | R25: =VLOOKUP(Q25,$B$44:$C$52,2) -> A | S25: 31 | T25: 36 | U25: =S25+T25 -> 67 | V25: =VLOOKUP(U25,$B$44:$C$52,2) -> C | W25: 24 | X25: 33 | Y25: =W25+X25 -> 57 | Z25: =VLOOKUP(Y25,$B$44:$C$52,2) -> D | AA25: 22 | AB25: 36 | AC25: =AA25+AB25 -> 58 | AD25: =VLOOKUP(AC25,$B$44:$C$52,2) -> D | AE25: 26 | AF25: 50 | AG25: =AE25+AF25 -> 76 | AH25: =VLOOKUP(AG25,$B$44:$C$52,2) -> B | AI25: 28 | AJ25: 39 | AK25: =AI25+AJ25 -> 67 | AL25: =VLOOKUP(AK25,$B$44:$C$52,2) -> C | AM25: 29.7 | AN25: 51 | AO25: =AM25+AN25 -> 80.7 | AP25: =VLOOKUP(AO25,$B$44:$C$52,2) -> A | AR25: =AVERAGE(E25,I25,M25,Q25,U25,Y25,AC25,AG25,AK25,AO25) -> 62.57 | AS25: =RANK(AR25,$AR$5:$AR$33) -> 13 | AT25: C | AU25: D | AV25: C | AW25: C | AX25: D | AY25: Lauzi shows an average level of behaviour, and she sometimes needs reminders to remain fully focused. Academically she performs well, demonstrating good understanding of classwork. To reach her full potential, she should work on staying attentive during lessons and organising her tasks more effectively. Setting small study goals at home will help reinforce learning. With improved focus and consistency, Lauzi can continue to grow academically.
A26: 22 | B26: Hasan Aaban | C26: 31 | D26: 35 | E26: =C26+D26 -> 66 | F26: =VLOOKUP(E26,$B$44:$C$52,2) -> C | G26: 13 | H26: 53 | I26: =G26+H26 -> 66 | J26: =VLOOKUP(I26,$B$44:$C$52,2) -> C | K26: 29 | L26: 38 | M26: =K26+L26 -> 67 | N26: =VLOOKUP(M26,$B$44:$C$52,2) -> C | O26: 32 | P26: 32 | Q26: =O26+P26 -> 64 | R26: =VLOOKUP(Q26,$B$44:$C$52,2) -> C | S26: 28 | T26: 40 | U26: =S26+T26 -> 68 | V26: =VLOOKUP(U26,$B$44:$C$52,2) -> C | W26: 32 | X26: 39 | Y26: =W26+X26 -> 71 | Z26: =VLOOKUP(Y26,$B$44:$C$52,2) -> B | AA26: 33 | AB26: 40 | AC26: =AA26+AB26 -> 73 | AD26: =VLOOKUP(AC26,$B$44:$C$52,2) -> B | AE26: 24 | AF26: 44 | AG26: =AE26+AF26 -> 68 | AH26: =VLOOKUP(AG26,$B$44:$C$52,2) -> C | AI26: 32 | AJ26: 42 | AK26: =AI26+AJ26 -> 74 | AL26: =VLOOKUP(AK26,$B$44:$C$52,2) -> B | AM26: 25 | AN26: 40 | AO26: =AM26+AN26 -> 65 | AP26: =VLOOKUP(AO26,$B$44:$C$52,2) -> C | AR26: =AVERAGE(E26,I26,M26,Q26,U26,Y26,AC26,AG26,AK26,AO26) -> 68.2 | AS26: =RANK(AR26,$AR$5:$AR$33) -> 9 | AT26: C | AU26: D | AV26: C | AW26: C | AX26: D | AY26: Aaban behaves reasonably well but is easily distracted, which affects his concentration in class. His academic performance is good when he remains focused. He needs to work on minimising distractions and staying engaged throughout lessons. Using short study routines and sitting away from distractions will support his progress. With improved concentration, Aaban can achieve even better results. I encourage him to stay committed and focused.
A27: 23 | B27: Malijani Kasonde | C27: 30 | D27: 46 | E27: =C27+D27 -> 76 | F27: B | G27: 25 | H27: 41 | I27: =G27+H27 -> 66 | J27: =VLOOKUP(I27,$B$44:$C$52,2) -> C | K27: 29 | L27: 49 | M27: =K27+L27 -> 78 | N27: =VLOOKUP(M27,$B$44:$C$52,2) -> B | O27: 35 | P27: 38 | Q27: =O27+P27 -> 73 | R27: =VLOOKUP(Q27,$B$44:$C$52,2) -> B | S27: 35 | T27: 51 | U27: =S27+T27 -> 86 | V27: =VLOOKUP(U27,$B$44:$C$52,2) -> A | W27: 34 | X27: 46 | Y27: =W27+X27 -> 80 | Z27: =VLOOKUP(Y27,$B$44:$C$52,2) -> A | AA27: 39 | AB27: 59 | AC27: =AA27+AB27 -> 98 | AD27: =VLOOKUP(AC27,$B$44:$C$52,2) -> A* | AE27: 35 | AF27: 52 | AG27: =AE27+AF27 -> 87 | AH27: =VLOOKUP(AG27,$B$44:$C$52,2) -> A | AI27: 37 | AJ27: 56 | AK27: =AI27+AJ27 -> 93 | AL27: =VLOOKUP(AK27,$B$44:$C$52,2) -> A* | AM27: 23 | AN27: 49 | AO27: =AM27+AN27 -> 72 | AP27: =VLOOKUP(AO27,$B$44:$C$52,2) -> B | AR27: =AVERAGE(E27,I27,M27,Q27,U27,Y27,AC27,AG27,AK27,AO27) -> 80.9 | AS27: =RANK(AR27,$AR$5:$AR$33) -> 1 | AT27: C | AU27: A+ | AV27: C | AW27: C | AX27: A | AY27: Kasonde is a very well-behaved learner who approaches her work positively. Her academic performance is good, and she completes tasks to a satisfactory standard. She can improve further by challenging herself with more complex questions and participating more actively in class. Regular home revision will also strengthen her understanding. Kasonde is encouraged to continue her positive approach and show confidence in her abilities.
A28: 24 | B28: Mwiimbwa Chileleko | C28: 35 | D28: 44 | E28: =C28+D28 -> 79 | F28: =VLOOKUP(E28,$B$44:$C$52,2) -> B | G28: 25 | H28: 44 | I28: =G28+H28 -> 69 | J28: =VLOOKUP(I28,$B$44:$C$52,2) -> C | L28: 48 | M28: =K28+L28 -> 48 | N28: =VLOOKUP(M28,$B$44:$C$52,2) -> E | O28: 31 | P28: 43 | Q28: =O28+P28 -> 74 | R28: =VLOOKUP(Q28,$B$44:$C$52,2) -> B | S28: 31 | T28: 42 | U28: =S28+T28 -> 73 | V28: =VLOOKUP(U28,$B$44:$C$52,2) -> B | W28: 32 | X28: 40 | Y28: =W28+X28 -> 72 | Z28: =VLOOKUP(Y28,$B$44:$C$52,2) -> B | AA28: 28 | AB28: 50 | AC28: =AA28+AB28 -> 78 | AD28: =VLOOKUP(AC28,$B$44:$C$52,2) -> B | AE28: 27 | AF28: 51 | AG28: =AE28+AF28 -> 78 | AH28: =VLOOKUP(AG28,$B$44:$C$52,2) -> B | AI28: 38 | AJ28: 43 | AK28: =AI28+AJ28 -> 81 | AL28: =VLOOKUP(AK28,$B$44:$C$52,2) -> A | AM28: 20 | AN28: 39 | AO28: =AM28+AN28 -> 59 | AP28: =VLOOKUP(AO28,$B$44:$C$52,2) -> D | AR28: =AVERAGE(E28,I28,M28,Q28,U28,Y28,AC28,AG28,AK28,AO28) -> 71.1 | AS28: =RANK(AR28,$AR$5:$AR$33) -> 8 | AT28: C | AU28: A | AV28: C | AW28: C | AX28: A | AY28: Chileleko is a very well-behaved student, though he needs to improve his punctuality as late-coming affects his learning. Academically, he performs well and shows clear potential for further success. He can make even greater progress by maintaining focus and completing tasks with deeper detail. Ensuring he arrives on time will benefit his overall performance. I encourage Chileleko to keep up his good work and improve his punctuality.
A29: 25 | B29: Omar
A30: 26 | B30: Adeaze
A31: 27 | B31: Elijah
A32: 28
AH33: =VLOOKUP(AG33,$B$44:$C$52,2) -> U
B36: Average | E36: =AVERAGE(E5:E28) -> 63.375 | I36: =AVERAGE(I5:I28) -> 46.458333 | M36: =AVERAGE(M5:M28) -> 53.208333 | Q36: =AVERAGE(Q5:Q28) -> 67.666667 | U36: =AVERAGE(U5:U28) -> 65.291667 | Y36: =AVERAGE(Y5:Y28) -> 63.375 | AC36: =AVERAGE(AC5:AC28) -> 61.333333 | AG36: =AVERAGE(AG5:AG28) -> 73.625 | AK36: =AVERAGE(AK5:AK28) -> 76.333333 | AO36: =AVERAGE(AO5:AO28) -> 66.941667
B37: NO. Students | E37: =COUNT(E5:E28) -> 24 | I37: =COUNT(I5:I28) -> 24 | M37: =COUNT(M5:M28) -> 24 | Q37: =COUNT(Q5:Q28) -> 24 | U37: =COUNT(U5:U28) -> 24 | Y37: =COUNT(Y5:Y28) -> 24 | AC37: =COUNT(AC5:AC28) -> 24 | AG37: =COUNT(AG5:AG28) -> 24 | AK37: =COUNT(AK5:AK28) -> 24 | AO37: =COUNT(AO5:AO28) -> 24
B38: Pass | E38: =COUNTIF($E$5:$E$28,">49") -> 21 | I38: =COUNTIF($I$5:$I$28,">49") -> 12 | M38: =COUNTIF($M$5:$M$28,">49") -> 11 | Q38: =COUNTIF($Q$5:$Q$28,">49") -> 21 | U38: =COUNTIF($U$5:$U$28,">49") -> 22 | Y38: =COUNTIF($Y$5:$Y$28,">49") -> 21 | AC38: =COUNTIF($AC$5:$AC$28,">49") -> 15 | AG38: =COUNTIF($AG$5:$AG$28,">49") -> 24 | AK38: =COUNTIF($AK$5:$AK$28,">49") -> 24 | AO38: =COUNTIF($AO$5:$AO$28,">49") -> 22
B39: Fail | E39: =COUNTIF(E5:E28,"<50") -> 3 | I39: =COUNTIF(I5:I28,"<50") -> 12 | M39: =COUNTIF(M5:M28,"<50") -> 13 | Q39: =COUNTIF(Q5:Q28,"<50") -> 3 | U39: =COUNTIF(U5:U28,"<50") -> 2 | Y39: =COUNTIF(Y5:Y28,"<50") -> 3 | AC39: =COUNTIF(AC5:AC28,"<50") -> 9 | AG39: =COUNTIF(AG5:AG28,"<50") -> 0 | AK39: =COUNTIF(AK5:AK28,"<50") -> 0 | AO39: =COUNTIF(AO5:AO28,"<50") -> 2
B40: Pass Rate % | E40: =E38*100/E37 -> 87.5 | I40: =I38*100/I37 -> 50 | M40: =M38*100/M37 -> 45.833333 | Q40: =Q38*100/Q37 -> 87.5 | U40: =U38*100/U37 -> 91.666667 | Y40: =Y38*100/Y37 -> 87.5 | AC40: =AC38*100/AC37 -> 62.5 | AG40: =AG38*100/AG37 -> 100 | AK40: =AK38*100/AK37 -> 100 | AO40: =AO38*100/AO37 -> 91.666667
A44: 00-19 | B44: 0 | C44: U
A45: 20-29 | B45: 20 | C45: G
A46: 30-39 | B46: 30 | C46: F
A47: 40-49 | B47: 40 | C47: E
...

Sheet LS1B
A1: HOME
A3: Roll N0. | B3: Name | C3: English | G3: Mathematics | K3: Science | O3: Global Perspectives | S3: New Computing | W3: Business Studies | AA3: French | AE3: Art | AI3: MDD | AM3: PE | AR3: AVERAGE | AS3: POSITION | AT3: CREATIVITY | AU3: RESPECT | AV3: EXCELLENCE | AW3: EMPATHY | AX3: DISCIPLINE | AY3: CLASS TEACHER'S COMMENT
C4: Formative | D4: Summative | E4: Final Mark | F4: Grade | G4: Formative | H4: Summative | I4: Final Mark | J4: Grade | K4: Formative | L4: Summative | M4: Final Mark | N4: Grade | O4: Formative | P4: Summative | Q4: Final Mark | R4: Grade | S4: Formative | T4: Summative | U4: Final Mark | V4: Grade | W4: Formative | X4: Summative | Y4: Final Mark | Z4: Grade | AA4: Formative | AB4: Summative | AC4: Final Mark | AD4: Grade | AE4: Formative | AF4: Summative | AG4: Final Mark | AH4: Grade | AI4: Formative | AJ4: Summative | AK4: Final Mark | AL4: Grade | AM4: Formative | AN4: Summative | AO4: Final Mark | AP4: Grade
A5: 1 | B5: Nhundu Nokutenda | C5: 28 | D5: 36 | E5: =C5+D5 -> 64 | F5: =VLOOKUP(E5,$B$43:$C$51,2) -> C | G5: 18 | H5: 21 | I5: =G5+H5 -> 39 | J5: =VLOOKUP(I5,$B$43:$C$51,2) -> F | K5: 21 | L5: 30.1 | M5: =K5+L5 -> 51.1 | N5: =VLOOKUP(M5,$B$43:$C$51,2) -> D | O5: 28 | P5: 42 | Q5: =O5+P5 -> 70 | R5: =VLOOKUP(Q5,$B$43:$C$51,2) -> B | S5: 20 | T5: 37 | U5: =S5+T5 -> 57 | V5: =VLOOKUP(U5,$B$43:$C$51,2) -> D | W5: 24 | X5: 42 | Y5: =W5+X5 -> 66 | Z5: =VLOOKUP(Y5,$B$43:$C$51,2) -> C | AA5: 27 | AB5: 36 | AC5: =AA5+AB5 -> 63 | AD5: =VLOOKUP(AC5,$B$43:$C$51,2) -> C | AE5: 27 | AF5: 55 | AG5: =AE5+AF5 -> 82 | AH5: =VLOOKUP(AG5,$B$43:$C$51,2) -> A | AI5: 25 | AJ5: 53 | AK5: =AI5+AJ5 -> 78 | AL5: =VLOOKUP(AK5,$B$43:$C$51,2) -> B | AM5: 20 | AN5: 47 | AO5: =AM5+AN5 -> 67 | AP5: =VLOOKUP(AO5,$B$43:$C$51,2) -> C | AR5: =AVERAGE(E5,I5,M5,Q5,U5,Y5,AC5,AG5,AK5,AO5) -> 63.71 | AS5: =RANK(AR5,$AR$5:$AR$32) -> 19 | AT5: A | AU5: A+ | AV5: A | AW5: A+ | AX5: A | AY5: Nokutenda shows generally good behavior in class, following instructions and participating in activities with a positive attitude. She is respectful toward teachers and classmates and complete assignments on time. However, there are times when her focus lapses, especially during independent work, and she would benefit from engaging more actively in class discussions. With increased concentration and confidence, Nokutenda has the potential to make even greater progress this term.
A6: 2 | B6: Maponga Taonga | C6: 29 | D6: 31 | E6: =C6+D6 -> 60 | F6: =VLOOKUP(E6,$B$43:$C$51,2) -> C | G6: 6 | H6: 13 | I6: =G6+H6 -> 19 | J6: =VLOOKUP(I6,$B$43:$C$51,2) -> U | K6: 17.8 | L6: 24 | M6: =K6+L6 -> 41.8 | N6: =VLOOKUP(M6,$B$43:$C$51,2) -> E | O6: 25 | P6: 27 | Q6: =O6+P6 -> 52 | R6: =VLOOKUP(Q6,$B$43:$C$51,2) -> D | S6: 19 | T6: 37 | U6: =S6+T6 -> 56 | V6: =VLOOKUP(U6,$B$43:$C$51,2) -> D | W6: 22 | X6: 28 | Y6: =W6+X6 -> 50 | Z6: =VLOOKUP(Y6,$B$43:$C$51,2) -> D | AA6: 17 | AB6: 31 | AC6: =AA6+AB6 -> 48 | AD6: =VLOOKUP(AC6,$B$43:$C$51,2) -> E | AE6: 27 | AF6: 44 | AG6: =AE6+AF6 -> 71 | AH6: =VLOOKUP(AG6,$B$43:$C$51,2) -> B | AI6: 28 | AJ6: 27 | AK6: =AI6+AJ6 -> 55 | AL6: =VLOOKUP(AK6,$B$43:$C$51,2) -> D | AM6: 19 | AN6: 45 | AO6: =AM6+AN6 -> 64 | AP6: =VLOOKUP(AO6,$B$43:$C$51,2) -> C | AR6: =AVERAGE(E6,I6,M6,Q6,U6,Y6,AC6,AG6,AK6,AO6) -> 51.68 | AS6: =RANK(AR6,$AR$5:$AR$32) -> 25 | AT6: B | AU6: A | AV6: A | AW6: A | AX6: B | AY6: Taonga is a polite and cooperative student who has shown some effort this term. However, his academic performance requires significant improvement, particularly in English, Mathematics, and Science, as well as in other subjects. He would benefit greatly from close monitoring, regular revision, and attending support classes. I encourage strong cooperation between home and school to support his progress.
A7: 3 | B7: Chilufya Loisa Njavwa | C7: 24 | D7: 39 | E7: =C7+D7 -> 63 | F7: =VLOOKUP(E7,$B$43:$C$51,2) -> C | G7: 14 | H7: 20 | I7: =G7+H7 -> 34 | J7: =VLOOKUP(I7,$B$43:$C$51,2) -> F | K7: 20.2 | L7: 28.8 | M7: =K7+L7 -> 49 | N7: =VLOOKUP(M7,$B$43:$C$51,2) -> E | O7: 29 | P7: 33 | Q7: =O7+P7 -> 62 | R7: =VLOOKUP(Q7,$B$43:$C$51,2) -> C | S7: 25 | T7: 47 | U7: =S7+T7 -> 72 | V7: =VLOOKUP(U7,$B$43:$C$51,2) -> B | W7: 39 | X7: 54 | Y7: =W7+X7 -> 93 | Z7: =VLOOKUP(Y7,$B$43:$C$51,2) -> A* | AA7: 28 | AB7: 36 | AC7: =AA7+AB7 -> 64 | AD7: =VLOOKUP(AC7,$B$43:$C$51,2) -> C | AE7: 28 | AF7: 50 | AG7: =AE7+AF7 -> 78 | AH7: =VLOOKUP(AG7,$B$43:$C$51,2) -> B | AI7: 43 | AJ7: 29 | AK7: =AI7+AJ7 -> 72 | AL7: =VLOOKUP(AK7,$B$43:$C$51,2) -> B | AM7: 20 | AN7: 45 | AO7: =AM7+AN7 -> 65 | AP7: =VLOOKUP(AO7,$B$43:$C$51,2) -> C | AR7: =AVERAGE(E7,I7,M7,Q7,U7,Y7,AC7,AG7,AK7,AO7) -> 65.2 | AS7: =RANK(AR7,$AR$5:$AR$32) -> 16 | AT7: A | AU7: B | AV7: B | AW7: A+ | AX7: B | AY7: Njavwa is an energetic and friendly learner who enjoys interacting with peers. Although she has the potential to perform well, her distractibility affects the quality of her work. She must improve her concentration and develop consistent study habits. Mathematics and Science especially require additional support. I recommend structured revision, limited distractions at home, and regular teacher-parent follow-ups.
A8: 4 | B8: Ncube Nkosazana | C8: 32 | D8: 40 | E8: =C8+D8 -> 72 | F8: =VLOOKUP(E8,$B$43:$C$51,2) -> B | G8: 14 | H8: 32 | I8: =G8+H8 -> 46 | J8: =VLOOKUP(I8,$B$43:$C$51,2) -> E | K8: 25 | L8: 30 | M8: =K8+L8 -> 55 | N8: =VLOOKUP(M8,$B$43:$C$51,2) -> D | O8: 28 | P8: 47 | Q8: =O8+P8 -> 75 | R8: =VLOOKUP(Q8,$B$43:$C$51,2) -> B | S8: 37 | T8: 50 | U8: =S8+T8 -> 87 | V8: =VLOOKUP(U8,$B$43:$C$51,2) -> A | W8: 26 | X8: 45 | Y8: =W8+X8 -> 71 | Z8: =VLOOKUP(Y8,$B$43:$C$51,2) -> B | AA8: 29 | AB8: 43 | AC8: =AA8+AB8 -> 72 | AD8: =VLOOKUP(AC8,$B$43:$C$51,2) -> B | AE8: 32 | AF8: 45 | AG8: =AE8+AF8 -> 77 | AH8: =VLOOKUP(AG8,$B$43:$C$51,2) -> B | AI8: 27 | AJ8: 47 | AK8: =AI8+AJ8 -> 74 | AL8: =VLOOKUP(AK8,$B$43:$C$51,2) -> B | AM8: 15 | AN8: 46 | AO8: =AM8+AN8 -> 61 | AP8: =VLOOKUP(AO8,$B$43:$C$51,2) -> C | AR8: =AVERAGE(E8,I8,M8,Q8,U8,Y8,AC8,AG8,AK8,AO8) -> 69 | AS8: =RANK(AR8,$AR$5:$AR$32) -> 11 | AT8: A | AU8: A+ | AV8: A | AW8: A+ | AX8: A+ | AY8: Nkosazana is a polite and cooperative student who has demonstrated some effort this term. However, her academic progress requires improvement, with Mathematics being a primary area of focus. To support her development, she would benefit greatly from close monitoring, consistent revision, and participation in support classes. I strongly encourage close collaboration between home and school to help Nkosazana build her confidence and skills. With targeted support and sustained effort, she has the potential to achieve stronger results.
A9: 5 | B9: Munshi Mahira | C9: 29 | D9: 42 | E9: =C9+D9 -> 71 | F9: =VLOOKUP(E9,$B$43:$C$51,2) -> B | G9: 21 | H9: 38 | I9: =G9+H9 -> 59 | J9: =VLOOKUP(I9,$B$43:$C$51,2) -> D | K9: 25 | L9: 30.6 | M9: =K9+L9 -> 55.6 | N9: =VLOOKUP(M9,$B$43:$C$51,2) -> D | O9: 24 | P9: 38 | Q9: =O9+P9 -> 62 | R9: =VLOOKUP(Q9,$B$43:$C$51,2) -> C | S9: 31 | T9: 44 | U9: =S9+T9 -> 75 | V9: =VLOOKUP(U9,$B$43:$C$51,2) -> B | W9: 32 | X9: 43 | Y9: =W9+X9 -> 75 | Z9: =VLOOKUP(Y9,$B$43:$C$51,2) -> B | AA9: 27 | AB9: 50 | AC9: =AA9+AB9 -> 77 | AD9: =VLOOKUP(AC9,$B$43:$C$51,2) -> B | AE9: 35 | AF9: 39 | AG9: =AE9+AF9 -> 74 | AH9: =VLOOKUP(AG9,$B$43:$C$51,2) -> B | AI9: 28 | AJ9: 34 | AK9: =AI9+AJ9 -> 62 | AL9: =VLOOKUP(AK9,$B$43:$C$51,2) -> C | AM9: 17.6 | AN9: 38 | AO9: =AM9+AN9 -> 55.6 | AP9: =VLOOKUP(AO9,$B$43:$C$51,2) -> D | AR9: =AVERAGE(E9,I9,M9,Q9,U9,Y9,AC9,AG9,AK9,AO9) -> 66.62 | AS9: =RANK(AR9,$AR$5:$AR$32) -> 14 | AT9: A+ | AU9: A | AV9: A | AW9: A+ | AX9: A | AY9: Mahira is a respectful and well-mannered student who relates well with peers and teachers. Despite her good behaviour, she needs to put more effort into her academic work, particularly in Mathematics and English and Science . She must develop stronger study habits and complete assignments more thoroughly. Close collaboration between home and school will help her unlock her potential.
A10: 6 | B10: Mavhunga Mukudzei | C10: 25 | D10: 39 | E10: =C10+D10 -> 64 | F10: =VLOOKUP(E10,$B$43:$C$51,2) -> C | G10: 27 | H10: 45 | I10: =G10+H10 -> 72 | J10: =VLOOKUP(I10,$B$43:$C$51,2) -> B | K10: 32.2 | L10: 39.6 | M10: =K10+L10 -> 71.8 | N10: =VLOOKUP(M10,$B$43:$C$51,2) -> B | O10: 26 | P10: 38 | Q10: =O10+P10 -> 64 | R10: =VLOOKUP(Q10,$B$43:$C$51,2) -> C | S10: 33 | T10: 48 | U10: =S10+T10 -> 81 | V10: =VLOOKUP(U10,$B$43:$C$51,2) -> A | W10: 27 | X10: 41 | Y10: =W10+X10 -> 68 | Z10: =VLOOKUP(Y10,$B$43:$C$51,2) -> C | AA10: 24 | AB10: 54 | AC10: =AA10+AB10 -> 78 | AD10: =VLOOKUP(AC10,$B$43:$C$51,2) -> B | AE10: 28 | AF10: 50 | AG10: =AE10+AF10 -> 78 | AH10: =VLOOKUP(AG10,$B$43:$C$51,2) -> B | AI10: 25 | AJ10: 48 | AK10: =AI10+AJ10 -> 73 | AL10: =VLOOKUP(AK10,$B$43:$C$51,2) -> B | AM10: 18.8 | AN10: 44 | AO10: =AM10+AN10 -> 62.8 | AP10: =VLOOKUP(AO10,$B$43:$C$51,2) -> C | AR10: =AVERAGE(E10,I10,M10,Q10,U10,Y10,AC10,AG10,AK10,AO10) -> 71.26 | AS10: =RANK(AR10,$AR$5:$AR$32) -> 6 | AT10: A+ | AU10: A+ | AV10: A | AW10: A | AX10: A+ | AY10: Mukudzei is an energetic and friendly learner who enjoys interacting with peers. Although he has the potential to perform well, his distractibility affects the quality of his work. He must improve his concentration and develop consistent study habits. English and Science especially require additional support. I recommend structured revision, limited distractions at home, and regular teacher-parent follow-ups.
A11: 7 | B11: Rakindas Rijith Hayagriv | C11: 32 | D11: 41 | E11: =C11+D11 -> 73 | F11: =VLOOKUP(E11,$B$43:$C$51,2) -> B | G11: 34 | H11: 52 | I11: =G11+H11 -> 86 | J11: =VLOOKUP(I11,$B$43:$C$51,2) -> A | K11: 37.6 | L11: 54.6 | M11: =K11+L11 -> 92.2 | N11: =VLOOKUP(M11,$B$43:$C$51,2) -> A* | O11: 31 | P11: 50 | Q11: =O11+P11 -> 81 | R11: =VLOOKUP(Q11,$B$43:$C$51,2) -> A | S11: 38 | T11: 51 | U11: =S11+T11 -> 89 | V11: =VLOOKUP(U11,$B$43:$C$51,2) -> A | W11: 35 | X11: 55 | Y11: =W11+X11 -> 90 | Z11: =VLOOKUP(Y11,$B$43:$C$51,2) -> A* | AA11: 33 | AB11: 56 | AC11: =AA11+AB11 -> 89 | AD11: =VLOOKUP(AC11,$B$43:$C$51,2) -> A | AE11: 29 | AF11: 53 | AG11: =AE11+AF11 -> 82 | AH11: =VLOOKUP(AG11,$B$43:$C$51,2) -> A | AI11: 27 | AJ11: 53 | AK11: =AI11+AJ11 -> 80 | AL11: =VLOOKUP(AK11,$B$43:$C$51,2) -> A | AM11: 24 | AN11: 38 | AO11: =AM11+AN11 -> 62 | AP11: =VLOOKUP(AO11,$B$43:$C$51,2) -> C | AR11: =AVERAGE(E11,I11,M11,Q11,U11,Y11,AC11,AG11,AK11,AO11) -> 82.42 | AS11: =RANK(AR11,$AR$5:$AR$32) -> 2 | AT11: A | AU11: B | AV11: A | AW11: B | AX11: B | AY11: Rijith consistently demonstrates very good behaviour and enthusiasm for learning. His academic performance is good across subjects. To further enrich his learning, he should continue developing his critical-thinking skills through independent tasks and wider reading. Participating even more confidently in class discussions will also benefit him. Jad is encouraged to maintain his high standards and keep up his excellent work.
A12: 8 | B12: Konnur Vibha | C12: 34 | D12: 44 | E12: =C12+D12 -> 78 | F12: =VLOOKUP(E12,$B$43:$C$51,2) -> B | G12: 32 | H12: 51 | I12: =G12+H12 -> 83 | J12: =VLOOKUP(I12,$B$43:$C$51,2) -> A | K12: 34.2 | L12: 54 | M12: =K12+L12 -> 88.2 | N12: =VLOOKUP(M12,$B$43:$C$51,2) -> A | O12: 34 | P12: 40 | Q12: =O12+P12 -> 74 | R12: =VLOOKUP(Q12,$B$43:$C$51,2) -> B | S12: 39 | T12: 55 | U12: =S12+T12 -> 94 | V12: =VLOOKUP(U12,$B$43:$C$51,2) -> A* | W12: 32 | X12: 55 | Y12: =W12+X12 -> 87 | Z12: =VLOOKUP(Y12,$B$43:$C$51,2) -> A | AA12: 36 | AB12: 58 | AC12: =AA12+AB12 -> 94 | AD12: =VLOOKUP(AC12,$B$43:$C$51,2) -> A* | AE12: 33 | AF12: 57 | AG12: =AE12+AF12 -> 90 | AH12: =VLOOKUP(AG12,$B$43:$C$51,2) -> A* | AI12: 31 | AJ12: 51 | AK12: =AI12+AJ12 -> 82 | AL12: =VLOOKUP(AK12,$B$43:$C$51,2) -> A | AM12: 20 | AN12: 36 | AO12: =AM12+AN12 -> 56 | AP12: =VLOOKUP(AO12,$B$43:$C$51,2) -> D | AR12: =AVERAGE(E12,I12,M12,Q12,U12,Y12,AC12,AG12,AK12,AO12) -> 82.62 | AS12: =RANK(AR12,$AR$5:$AR$32) -> 1 | AT12: A+ | AU12: A+ | AV12: A+ | AW12: A+ | AX12: A+ | AY12: Vibha maintains good behaviour and displays a positive attitude towards learning. Her academic performance is strong, and she consistently produces good work. To reach even higher levels, she should continue building her confidence in class discussions and challenge herself with extended tasks. Maintaining her current study habits and practising regular revision will help her excel. I encourage Vibha to keep up her excellent attitude and continue striving for excellence.
